#VRML_SIM R2020b utf8
WorldInfo {
  title "Robo fotbal"
  coordinateSystem "NUE"
}
Viewpoint {
  orientation 0.5708973788356756 0.7809631265559235 0.25332346476106693 5.2672428372418985
  position -0.9773984170994274 0.6505334099213455 0.8232332676785168
}
TexturedBackground {
  texture "stadium"
}
TexturedBackgroundLight {
}
DEF stadium Solid {
  scale 0.15 0.15 0.15
  children [
    Shape {
      appearance DEF GREEN_APPEARANCE PBRAppearance {
        baseColorMap ImageTexture {
          url [
            "textures/field_quarter_base_color.jpg"
          ]
          repeatS FALSE
          repeatT FALSE
        }
        roughness 1
        metalness 0
        normalMap ImageTexture {
          url [
            "textures/field_quarter_normal.jpg"
          ]
          repeatS FALSE
          repeatT FALSE
        }
        occlusionMap ImageTexture {
          url [
            "textures/field_quarter_occlusion.jpg"
          ]
          repeatS FALSE
          repeatT FALSE
        }
      }
      geometry IndexedFaceSet {
        coord DEF QUATER_COORDS Coordinate {
          point [
            5.2 0 3.7
            0 0 3.7
            -5.2 0 3.7
            5.2 0 0
            0 0 0
            -5.2 0 0
            5.2 0 -3.7
            0 0 -3.7
            -5.2 0 -3.7
          ]
        }
        texCoord TextureCoordinate {
          point [
            0 0
            1 0
            1 1
            0 1
          ]
        }
        coordIndex [
          3, 4, 1, 0, -1, 4, 5, 2, 1, -1
          6, 7, 4, 3, -1, 7, 8, 5, 4, -1
        ]
        texCoordIndex [
          0, 1, 2, 3, -1, 1, 0, 3, 2, -1
          3, 2, 1, 0, -1, 2, 3, 0, 1, -1
        ]
      }
    }
    DEF WALL_OUTSIDE Shape {
      appearance PBRAppearance {
        baseColorMap ImageTexture {
          url [
            "textures/cyberbotics_logo.png"
          ]
        }
        roughness 0.5
        metalness 0
        textureTransform TextureTransform {
          scale 5 1
        }
      }
      geometry IndexedFaceSet {
        coord DEF WALL_COORDS Coordinate {
          point [
            5.22 0 3.72
            5.2 0 3.7
            -5.22 0 3.72
            -5.2 0 3.7
            5.22 0 -3.72
            5.2 0 -3.7
            -5.22 0 -3.72
            -5.2 0 -3.7
            5.22 0.3 3.72
            5.2 0.3 3.7
            -5.22 0.3 3.72
            -5.2 0.3 3.7
            5.22 0.3 -3.72
            5.2 0.3 -3.7
            -5.22 0.3 -3.72
            -5.2 0.3 -3.7
          ]
        }
        texCoord TextureCoordinate {
          point [
            0 0
            1 0
            1 1
            0 1
          ]
        }
        coordIndex [
          4, 6, 14, 12, -1, 2, 0, 8, 10, -1, 6, 2, 10, 14, -1, 0, 4, 12, 8, -1, 9, 11, 10, 8, -1, 15, 13, 12, 14, -1, 11, 15, 14, 10, -1, 9, 8, 12, 13, -1
        ]
        texCoordIndex [
          0, 1, 2, 3, -1, 0, 1, 2, 3, -1, 0, 1, 2, 3, -1, 0, 1, 2, 3, -1, 0, 0, 0, 0, -1, 0, 0, 0, 0, -1, 0, 0, 0, 0, -1, 0, 0, 0, 0, -1
        ]
      }
    }
    DEF WALL_INSIDE Shape {
      appearance PBRAppearance {
        baseColorMap ImageTexture {
          url [
            "textures/webots_logo.png"
          ]
        }
        roughness 0.5
        metalness 0
        textureTransform TextureTransform {
          scale 5 1
        }
      }
      geometry IndexedFaceSet {
        coord USE WALL_COORDS
        texCoord TextureCoordinate {
          point [
            0 0
            1 0
            1 1
            0 1
          ]
        }
        coordIndex [
          1, 3, 11, 9, -1, 7, 5, 13, 15, -1
          3, 7, 15, 11, -1, 5, 1, 9, 13, -1
        ]
        texCoordIndex [
          0, 1, 2, 3, -1, 0, 1, 2, 3, -1
          0, 1, 2, 3, -1, 0, 1, 2, 3, -1
        ]
      }
    }
    Solid {
      translation 4.55 0 0
      children [
        DEF HORIZONTAL_POST_TRANS Transform {
          translation 0 0.85 0
          rotation 1 0 0 1.5708
          children [
            Shape {
              appearance DEF POST_APP PBRAppearance {
                roughness 0.2
                metalness 0
              }
              geometry Capsule {
                height 1.6
                radius 0.05
              }
            }
          ]
        }
        DEF RIGHT_POST_TRANS Transform {
          translation 0 0.425 -0.8
          children [
            Shape {
              appearance USE POST_APP
              geometry Cylinder {
                bottom FALSE
                height 0.85
                radius 0.05
                top FALSE
              }
            }
          ]
        }
        DEF LEFT_POST_TRANS Transform {
          translation 0 0.425 0.8
          children [
            Shape {
              appearance USE POST_APP
              geometry Cylinder {
                bottom FALSE
                height 0.85
                radius 0.05
                top FALSE
              }
            }
          ]
        }
        Shape {
          appearance DEF NET_APP PBRAppearance {
            baseColorMap ImageTexture {
              url [
                "textures/net.png"
              ]
            }
            roughness 1
            metalness 0
          }
          geometry IndexedFaceSet {
            coord Coordinate {
              point [
                0.5 0 -0.8
                0.5 0 0.8
                0.5 0.85 0.8
                0.5 0.85 -0.8
                0.05 0 0.8
                0.05 0 -0.8
                0.05 0.85 0.8
                0.05 0.85 -0.8
              ]
            }
            texCoord TextureCoordinate {
              point [
                0 0
                28 0
                28 16
                0 16
                7 0
                7 16
                0 16
                28 0
                28 6
                0 6
              ]
            }
            coordIndex [
              0, 1, 2, 3, -1, 3, 2, 1, 0, -1, 1, 4, 6, 2, -1, 2, 6, 4, 1, -1, 0, 5, 7, 3, -1, 3, 7, 5, 0, -1, 2, 3, 7, 6, -1, 6, 7, 3, 2, -1
            ]
            texCoordIndex [
              0, 1, 2, 3, -1, 0, 1, 2, 3, -1, 0, 4, 5, 6, -1, 0, 4, 5, 6, -1, 0, 4, 5, 6, -1, 0, 4, 5, 6, -1, 0, 7, 8, 9, -1, 0, 7, 8, 9, -1
            ]
          }
        }
        Transform {
          translation 0.5 0.85 0
          rotation 1 0 0 1.5708
          children [
            DEF SMALL_HORIZONTAL_POST_SHAPE Shape {
              appearance USE POST_APP
              geometry Capsule {
                height 1.6
                radius 0.014
              }
            }
          ]
        }
        Transform {
          translation 0.5 0.007 0
          rotation 1 0 0 1.5708
          children [
            USE SMALL_HORIZONTAL_POST_SHAPE
          ]
        }
        Transform {
          translation 0.5 0.425 0.8
          children [
            DEF SMALL_POST_SHAPE Shape {
              appearance USE POST_APP
              geometry Cylinder {
                bottom FALSE
                height 0.85
                radius 0.014
                top FALSE
              }
            }
          ]
        }
        Transform {
          translation 0.5 0.425 -0.8
          children [
            USE SMALL_POST_SHAPE
          ]
        }
        Transform {
          translation 0.25 0.85 0.8
          rotation 0 0 1 1.5708
          children [
            DEF OTHER_SMALL_POST_SHAPE Shape {
              appearance USE POST_APP
              geometry Cylinder {
                bottom FALSE
                height 0.5
                radius 0.014
                top FALSE
              }
            }
          ]
        }
        Transform {
          translation 0.25 0.85 -0.8
          rotation 0 0 1 1.5708
          children [
            USE OTHER_SMALL_POST_SHAPE
          ]
        }
        Transform {
          translation 0.25 0.007 0.8
          rotation 0 0 1 1.5708
          children [
            USE OTHER_SMALL_POST_SHAPE
          ]
        }
        Transform {
          translation 0.25 0.007 -0.8
          rotation 0 0 1 1.5708
          children [
            USE OTHER_SMALL_POST_SHAPE
          ]
        }
      ]
      name "goal 1"
      model "robotstadium goal"
      boundingObject Group {
        children [
          USE HORIZONTAL_POST_TRANS
          USE RIGHT_POST_TRANS
          USE LEFT_POST_TRANS
          Transform {
            translation 0.275 0.425 -0.8
            children [
              DEF GOAL_SIDE_BOX Box {
                size 0.45 0.85 0.04
              }
            ]
          }
          Transform {
            translation 0.275 0.425 0.8
            children [
              USE GOAL_SIDE_BOX
            ]
          }
          Transform {
            translation 0.6 0.425 0
            children [
              Box {
                size 0.2 0.85 1.64
              }
            ]
          }
        ]
      }
      locked TRUE
    }
    Solid {
      translation -4.55 0 0
      rotation 0 1 0 3.14159
      children [
        DEF HORIZONTAL_POST_TRANS Transform {
          translation 0 0.85 0
          rotation 1 0 0 1.5708
          children [
            Shape {
              appearance DEF POST_APP PBRAppearance {
                roughness 0.2
                metalness 0
              }
              geometry Capsule {
                height 1.6
                radius 0.05
              }
            }
          ]
        }
        DEF RIGHT_POST_TRANS Transform {
          translation 0 0.425 -0.8
          children [
            Shape {
              appearance USE POST_APP
              geometry Cylinder {
                bottom FALSE
                height 0.85
                radius 0.05
                top FALSE
              }
            }
          ]
        }
        DEF LEFT_POST_TRANS Transform {
          translation 0 0.425 0.8
          children [
            Shape {
              appearance USE POST_APP
              geometry Cylinder {
                bottom FALSE
                height 0.85
                radius 0.05
                top FALSE
              }
            }
          ]
        }
        Shape {
          appearance DEF NET_APP PBRAppearance {
            baseColorMap ImageTexture {
              url [
                "textures/net.png"
              ]
            }
            roughness 1
            metalness 0
          }
          geometry IndexedFaceSet {
            coord Coordinate {
              point [
                0.5 0 -0.8
                0.5 0 0.8
                0.5 0.85 0.8
                0.5 0.85 -0.8
                0.05 0 0.8
                0.05 0 -0.8
                0.05 0.85 0.8
                0.05 0.85 -0.8
              ]
            }
            texCoord TextureCoordinate {
              point [
                0 0
                28 0
                28 16
                0 16
                7 0
                7 16
                0 16
                28 0
                28 6
                0 6
              ]
            }
            coordIndex [
              0, 1, 2, 3, -1, 3, 2, 1, 0, -1, 1, 4, 6, 2, -1, 2, 6, 4, 1, -1, 0, 5, 7, 3, -1, 3, 7, 5, 0, -1, 2, 3, 7, 6, -1, 6, 7, 3, 2, -1
            ]
            texCoordIndex [
              0, 1, 2, 3, -1, 0, 1, 2, 3, -1, 0, 4, 5, 6, -1, 0, 4, 5, 6, -1, 0, 4, 5, 6, -1, 0, 4, 5, 6, -1, 0, 7, 8, 9, -1, 0, 7, 8, 9, -1
            ]
          }
        }
        Transform {
          translation 0.5 0.85 0
          rotation 1 0 0 1.5708
          children [
            DEF SMALL_HORIZONTAL_POST_SHAPE Shape {
              appearance USE POST_APP
              geometry Capsule {
                height 1.6
                radius 0.014
              }
            }
          ]
        }
        Transform {
          translation 0.5 0.007 0
          rotation 1 0 0 1.5708
          children [
            USE SMALL_HORIZONTAL_POST_SHAPE
          ]
        }
        Transform {
          translation 0.5 0.425 0.8
          children [
            DEF SMALL_POST_SHAPE Shape {
              appearance USE POST_APP
              geometry Cylinder {
                bottom FALSE
                height 0.85
                radius 0.014
                top FALSE
              }
            }
          ]
        }
        Transform {
          translation 0.5 0.425 -0.8
          children [
            USE SMALL_POST_SHAPE
          ]
        }
        Transform {
          translation 0.25 0.85 0.8
          rotation 0 0 1 1.5708
          children [
            DEF OTHER_SMALL_POST_SHAPE Shape {
              appearance USE POST_APP
              geometry Cylinder {
                bottom FALSE
                height 0.5
                radius 0.014
                top FALSE
              }
            }
          ]
        }
        Transform {
          translation 0.25 0.85 -0.8
          rotation 0 0 1 1.5708
          children [
            USE OTHER_SMALL_POST_SHAPE
          ]
        }
        Transform {
          translation 0.25 0.007 0.8
          rotation 0 0 1 1.5708
          children [
            USE OTHER_SMALL_POST_SHAPE
          ]
        }
        Transform {
          translation 0.25 0.007 -0.8
          rotation 0 0 1 1.5708
          children [
            USE OTHER_SMALL_POST_SHAPE
          ]
        }
      ]
      name "goal 2"
      model "robotstadium goal"
      boundingObject Group {
        children [
          USE HORIZONTAL_POST_TRANS
          USE RIGHT_POST_TRANS
          USE LEFT_POST_TRANS
          Transform {
            translation 0.275 0.425 -0.8
            children [
              DEF GOAL_SIDE_BOX Box {
                size 0.45 0.85 0.04
              }
            ]
          }
          Transform {
            translation 0.275 0.425 0.8
            children [
              USE GOAL_SIDE_BOX
            ]
          }
          Transform {
            translation 0.6 0.425 0
            children [
              Box {
                size 0.2 0.85 1.64
              }
            ]
          }
        ]
      }
      locked TRUE
    }
  ]
  name "robotstadium soccer field"
  model "robotstadium soccer field"
  boundingObject Group {
    children [
      Plane {
        size 10.4 7.4
      }
      Transform {
        translation 5.2 0.15 0
        rotation 0 0 1 1.5708
        children [
          Box {
            size 0.3 0.02 7.4
          }
        ]
      }
      Transform {
        translation -5.2 0.15 0
        rotation 0 0 1 -1.5708
        children [
          Box {
            size 0.3 0.02 7.4
          }
        ]
      }
      Transform {
        translation 0 0.15 3.7
        rotation 1 0 0 -1.5708
        children [
          Box {
            size 10.4 0.02 0.3
          }
        ]
      }
      Transform {
        translation 0 0.15 -3.7
        rotation 1 0 0 1.5708
        children [
          Box {
            size 10.4 0.02 0.3
          }
        ]
      }
    ]
  }
  locked TRUE
}
DEF ball Solid {
  translation 0 0.019843163701321446 0
  children [
    DEF FOOTBALL_SHAPE Shape {
      appearance PBRAppearance {
        baseColorMap ImageTexture {
          url [
            "textures/football_base_color.jpg"
          ]
        }
        roughness 0.4
        metalness 0
        normalMap ImageTexture {
          url [
            "textures/football_normal.jpg"
          ]
        }
      }
      geometry Sphere {
        radius 0.02
        subdivision 3
      }
    }
  ]
  name "soccer ball"
  model "soccer ball"
  boundingObject USE FOOTBALL_SHAPE
  physics Physics {
    density -1
    mass 0.1
  }
  recognitionColors [
    1 1 1
    0 0 0
  ]
  linearVelocity 0 -9.67362187829133e-07 0
}
DEF player1 Robot {
  translation 0.46 0.05 -0.14
  rotation -2.3464099999870814e-06 0.9999999999944944 2.3464099999870814e-06 -1.5707953071795862
  children [
    DEF gps2 GPS {
      translation 0 0.06 -0.02
      children [
        Shape {
          appearance PBRAppearance {
          }
          geometry Box {
            size 0.001 0.1 0.001
          }
        }
      ]
      name "gps2"
    }
    DEF ds_R DistanceSensor {
      translation -0.02 0.015 0.03
      rotation 0 1 0 -1.57
      children [
        DEF ds Shape {
          appearance PBRAppearance {
          }
          geometry Box {
            size 0.005 0.005 0.005
          }
        }
      ]
      name "ds_R"
      boundingObject USE ds
      physics Physics {
      }
    }
    DEF ds_L DistanceSensor {
      translation 0.02 0.015 0.029968
      rotation 0 1 0 -1.57
      children [
        DEF ds Shape {
          appearance PBRAppearance {
          }
          geometry Box {
            size 0.005 0.005 0.005
          }
        }
      ]
      name "ds_L"
      boundingObject USE ds
      physics Physics {
      }
    }
    HingeJoint {
      jointParameters HingeJointParameters {
        anchor -0.035 -0.015 0
      }
      device [
        RotationalMotor {
          name "mot2"
        }
      ]
      endPoint Solid {
        translation -0.035 -0.015 0
        rotation 0 0 1 1.57
        children [
          DEF wh2 Shape {
            appearance PBRAppearance {
            }
            geometry Cylinder {
              height 0.01
              radius 0.015
            }
          }
        ]
        name "solid(1)"
        boundingObject USE wh2
        physics Physics {
        }
      }
    }
    HingeJoint {
      jointParameters HingeJointParameters {
        anchor 0.035 -0.015 0
      }
      device [
        RotationalMotor {
          name "mot1"
        }
      ]
      endPoint Solid {
        translation 0.035 -0.015 0
        rotation 0 0 1 1.57
        children [
          DEF wh1 Shape {
            appearance PBRAppearance {
            }
            geometry Cylinder {
              height 0.01
              radius 0.015
            }
          }
        ]
        boundingObject USE wh1
        physics Physics {
        }
      }
    }
    DEF body1 Transform {
      children [
        DEF body1 Shape {
          appearance PBRAppearance {
            baseColor 1 0 0
          }
          geometry Cylinder {
            height 0.05
            radius 0.03
          }
        }
      ]
    }
  ]
  boundingObject USE body1
  physics Physics {
  }
  controller "player1_controller"
}
DEF player3 Robot {
  translation 0.57 0.05 0.06
  rotation 0 1 0 -1.5707953071795862
  children [
    DEF gps2 GPS {
      translation 0 0.06 -0.02
      children [
        Shape {
          appearance PBRAppearance {
          }
          geometry Box {
            size 0.001 0.1 0.001
          }
        }
      ]
      name "gps2"
    }
    DEF ds_R DistanceSensor {
      translation -0.02 0.015 0.03
      rotation 0 1 0 -1.57
      children [
        DEF ds Shape {
          appearance PBRAppearance {
          }
          geometry Box {
            size 0.005 0.005 0.005
          }
        }
      ]
      name "ds_R"
      boundingObject USE ds
      physics Physics {
      }
    }
    DEF ds_L DistanceSensor {
      translation 0.02 0.015 0.029968
      rotation 0 1 0 -1.57
      children [
        DEF ds Shape {
          appearance PBRAppearance {
          }
          geometry Box {
            size 0.005 0.005 0.005
          }
        }
      ]
      name "ds_L"
      boundingObject USE ds
      physics Physics {
      }
    }
    HingeJoint {
      jointParameters HingeJointParameters {
        anchor -0.035 -0.015 0
      }
      device [
        RotationalMotor {
          name "mot2"
        }
      ]
      endPoint Solid {
        translation -0.035 -0.015 0
        rotation 0 0 1 1.57
        children [
          DEF wh2 Shape {
            appearance PBRAppearance {
            }
            geometry Cylinder {
              height 0.01
              radius 0.015
            }
          }
        ]
        name "solid(1)"
        boundingObject USE wh2
        physics Physics {
        }
      }
    }
    HingeJoint {
      jointParameters HingeJointParameters {
        anchor 0.035 -0.015 0
      }
      device [
        RotationalMotor {
          name "mot1"
        }
      ]
      endPoint Solid {
        translation 0.035 -0.015 0
        rotation 0 0 1 1.57
        children [
          DEF wh1 Shape {
            appearance PBRAppearance {
            }
            geometry Cylinder {
              height 0.01
              radius 0.015
            }
          }
        ]
        boundingObject USE wh1
        physics Physics {
        }
      }
    }
    DEF body1 Transform {
      children [
        DEF body1 Shape {
          appearance PBRAppearance {
            baseColor 1 0 0
          }
          geometry Cylinder {
            height 0.05
            radius 0.03
          }
        }
      ]
    }
  ]
  name "robot(2)"
  boundingObject USE body1
  physics Physics {
  }
  controller "player1_controller"
}
DEF player4 Robot {
  translation -0.11 0.03 0.0099994
  rotation 0 1 0 1.5708
  children [
    DEF gps2 GPS {
      translation 0 0.06 -0.02
      children [
        Shape {
          appearance PBRAppearance {
          }
          geometry Box {
            size 0.001 0.1 0.001
          }
        }
      ]
      name "gps2"
    }
    DEF ds_R DistanceSensor {
      translation -0.02 0.015 0.03
      rotation 0 1 0 -1.57
      children [
        DEF ds Shape {
          appearance PBRAppearance {
          }
          geometry Box {
            size 0.005 0.005 0.005
          }
        }
      ]
      name "ds_R"
      boundingObject USE ds
      physics Physics {
      }
    }
    DEF ds_L DistanceSensor {
      translation 0.02 0.015 0.029968
      rotation 0 1 0 -1.57
      children [
        DEF ds Shape {
          appearance PBRAppearance {
          }
          geometry Box {
            size 0.005 0.005 0.005
          }
        }
      ]
      name "ds_L"
      boundingObject USE ds
      physics Physics {
      }
    }
    HingeJoint {
      jointParameters HingeJointParameters {
        anchor -0.035 -0.015 0
      }
      device [
        RotationalMotor {
          name "mot2"
        }
      ]
      endPoint Solid {
        translation -0.035 -0.015 0
        rotation 0 0 1 1.57
        children [
          DEF wh2 Shape {
            appearance PBRAppearance {
            }
            geometry Cylinder {
              height 0.01
              radius 0.015
            }
          }
        ]
        name "solid(1)"
        boundingObject USE wh2
        physics Physics {
        }
      }
    }
    HingeJoint {
      jointParameters HingeJointParameters {
        anchor 0.035 -0.015 0
      }
      device [
        RotationalMotor {
          name "mot1"
        }
      ]
      endPoint Solid {
        translation 0.035 -0.015 0
        rotation 0 0 1 1.57
        children [
          DEF wh1 Shape {
            appearance PBRAppearance {
            }
            geometry Cylinder {
              height 0.01
              radius 0.015
            }
          }
        ]
        boundingObject USE wh1
        physics Physics {
        }
      }
    }
    DEF body1 Transform {
      children [
        DEF body1 Shape {
          appearance PBRAppearance {
            baseColor 0 0 1
          }
          geometry Cylinder {
            height 0.05
            radius 0.03
          }
        }
      ]
    }
  ]
  name "robot(3)"
  boundingObject USE body1
  physics Physics {
  }
  controller "player1_controller"
}
DEF player5 Robot {
  translation 0.15 0.03 3.05885e-08
  rotation 0 1 0 -1.5707953071795862
  children [
    DEF gps2 GPS {
      translation 0 0.06 -0.02
      children [
        Shape {
          appearance PBRAppearance {
          }
          geometry Box {
            size 0.001 0.1 0.001
          }
        }
      ]
      name "gps2"
    }
    DEF ds_R DistanceSensor {
      translation -0.02 0.015 0.03
      rotation 0 1 0 -1.57
      children [
        DEF ds Shape {
          appearance PBRAppearance {
          }
          geometry Box {
            size 0.005 0.005 0.005
          }
        }
      ]
      name "ds_R"
      boundingObject USE ds
      physics Physics {
      }
    }
    DEF ds_L DistanceSensor {
      translation 0.02 0.015 0.029968
      rotation 0 1 0 -1.57
      children [
        DEF ds Shape {
          appearance PBRAppearance {
          }
          geometry Box {
            size 0.005 0.005 0.005
          }
        }
      ]
      name "ds_L"
      boundingObject USE ds
      physics Physics {
      }
    }
    HingeJoint {
      jointParameters HingeJointParameters {
        anchor -0.035 -0.015 0
      }
      device [
        RotationalMotor {
          name "mot2"
        }
      ]
      endPoint Solid {
        translation -0.035 -0.015 0
        rotation 0 0 1 1.57
        children [
          DEF wh2 Shape {
            appearance PBRAppearance {
            }
            geometry Cylinder {
              height 0.01
              radius 0.015
            }
          }
        ]
        name "solid(1)"
        boundingObject USE wh2
        physics Physics {
        }
      }
    }
    HingeJoint {
      jointParameters HingeJointParameters {
        anchor 0.035 -0.015 0
      }
      device [
        RotationalMotor {
          name "mot1"
        }
      ]
      endPoint Solid {
        translation 0.035 -0.015 0
        rotation 0 0 1 1.57
        children [
          DEF wh1 Shape {
            appearance PBRAppearance {
            }
            geometry Cylinder {
              height 0.01
              radius 0.015
            }
          }
        ]
        boundingObject USE wh1
        physics Physics {
        }
      }
    }
    DEF body1 Transform {
      children [
        DEF body1 Shape {
          appearance PBRAppearance {
            baseColor 1 0 0
          }
          geometry Cylinder {
            height 0.05
            radius 0.03
          }
        }
      ]
    }
  ]
  name "robot(4)"
  boundingObject USE body1
  physics Physics {
  }
  controller "player1_controller"
}
DEF player6 Robot {
  translation -0.38 0.05 -0.26
  rotation 0 1 0 1.5708
  children [
    DEF gps2 GPS {
      translation 0 0.06 -0.02
      children [
        Shape {
          appearance PBRAppearance {
          }
          geometry Box {
            size 0.001 0.1 0.001
          }
        }
      ]
      name "gps2"
    }
    DEF ds_R DistanceSensor {
      translation -0.02 0.015 0.03
      rotation 0 1 0 -1.57
      children [
        DEF ds Shape {
          appearance PBRAppearance {
          }
          geometry Box {
            size 0.005 0.005 0.005
          }
        }
      ]
      name "ds_R"
      boundingObject USE ds
      physics Physics {
      }
    }
    DEF ds_L DistanceSensor {
      translation 0.02 0.015 0.029968
      rotation 0 1 0 -1.57
      children [
        DEF ds Shape {
          appearance PBRAppearance {
          }
          geometry Box {
            size 0.005 0.005 0.005
          }
        }
      ]
      name "ds_L"
      boundingObject USE ds
      physics Physics {
      }
    }
    HingeJoint {
      jointParameters HingeJointParameters {
        anchor -0.035 -0.015 0
      }
      device [
        RotationalMotor {
          name "mot2"
        }
      ]
      endPoint Solid {
        translation -0.035 -0.015 0
        rotation 0 0 1 1.57
        children [
          DEF wh2 Shape {
            appearance PBRAppearance {
            }
            geometry Cylinder {
              height 0.01
              radius 0.015
            }
          }
        ]
        name "solid(1)"
        boundingObject USE wh2
        physics Physics {
        }
      }
    }
    HingeJoint {
      jointParameters HingeJointParameters {
        anchor 0.035 -0.015 0
      }
      device [
        RotationalMotor {
          name "mot1"
        }
      ]
      endPoint Solid {
        translation 0.035 -0.015 0
        rotation 0 0 1 1.57
        children [
          DEF wh1 Shape {
            appearance PBRAppearance {
            }
            geometry Cylinder {
              height 0.01
              radius 0.015
            }
          }
        ]
        boundingObject USE wh1
        physics Physics {
        }
      }
    }
    DEF body1 Transform {
      children [
        DEF body1 Shape {
          appearance PBRAppearance {
            baseColor 0 0 1
          }
          geometry Cylinder {
            height 0.05
            radius 0.03
          }
        }
      ]
    }
  ]
  name "robot(5)"
  boundingObject USE body1
  physics Physics {
  }
  controller "player1_controller"
}
DEF player2 Robot {
  translation -0.6 0.05 -0.01
  rotation 0 1 0 1.5708
  children [
    DEF gps3 GPS {
      translation 0 0.06 -0.02
      children [
        Shape {
          appearance PBRAppearance {
          }
          geometry Box {
            size 0.001 0.1 0.001
          }
        }
      ]
      name "gps3"
    }
    DEF ds_R DistanceSensor {
      translation -0.02 0.015 0.03
      rotation 0 1 0 -1.57
      children [
        DEF ds Shape {
          appearance PBRAppearance {
          }
          geometry Box {
            size 0.005 0.005 0.005
          }
        }
      ]
      name "ds_R"
      boundingObject USE ds
      physics Physics {
      }
    }
    DEF ds_L DistanceSensor {
      translation 0.02 0.015 0.029968
      rotation 0 1 0 -1.57
      children [
        DEF ds Shape {
          appearance PBRAppearance {
          }
          geometry Box {
            size 0.005 0.005 0.005
          }
        }
      ]
      name "ds_L"
      boundingObject USE ds
      physics Physics {
      }
    }
    HingeJoint {
      jointParameters HingeJointParameters {
        anchor -0.035 -0.015 0
      }
      device [
        RotationalMotor {
          name "mot2"
        }
      ]
      endPoint Solid {
        translation -0.035 -0.015 0
        rotation 0 0 1 1.57
        children [
          DEF wh2 Shape {
            appearance PBRAppearance {
            }
            geometry Cylinder {
              height 0.01
              radius 0.015
            }
          }
        ]
        name "solid(1)"
        boundingObject USE wh2
        physics Physics {
        }
      }
    }
    HingeJoint {
      jointParameters HingeJointParameters {
        anchor 0.035 -0.015 0
      }
      device [
        RotationalMotor {
          name "mot1"
        }
      ]
      endPoint Solid {
        translation 0.035 -0.015 0
        rotation 0 0 1 1.57
        children [
          DEF wh1 Shape {
            appearance PBRAppearance {
            }
            geometry Cylinder {
              height 0.01
              radius 0.015
            }
          }
        ]
        boundingObject USE wh1
        physics Physics {
        }
      }
    }
    DEF body1 Transform {
      children [
        DEF body1 Shape {
          appearance PBRAppearance {
            baseColor 0 0 1
          }
          geometry Cylinder {
            height 0.05
            radius 0.03
          }
        }
      ]
    }
  ]
  name "robot(1)"
  boundingObject USE body1
  physics Physics {
  }
  controller "player1_controller"
}
